Workbook

Sheet README
A1: Triple-Leak BF Opportunity Sizing Model
A3: PURPOSE
A4: Interactive sizing tool for 3-cohort Black Friday revenue leakage recovery program.
A5: Stakeholders change assumptions (yellow cells) → see impact on recovery $ (green cells).
A7: SHEETS
A8: 1. Assumptions — User-editable inputs (yellow). Change here to see impact everywhere.
A9: 2. Verified_Data — DA-verified numbers (blue). DO NOT EDIT. Stamped from Phase 5+6.
A10: 3. Calculations — Core formulas per cohort × scenario (green = output).
A11: 4. Scenarios — Conservative / Base / Optimistic side-by-side.
A12: 5. Sensitivity — Recovery rate × discount cost heatmap for base case.
A13: 6. Annual_Projection — 7 flash sale events compounding.
A15: COLOR CODE
... A31: Total addressable: $337.5M (89% of $377.9M Nov GMV at risk, exclude Nov 15).

Sheet Verified_Data
A1: Verified Data from DA Phase 5+6
A2: DO NOT EDIT — locked source of truth
A5: TOTAL BF METRICS
A6: Total Nov GMV at risk (excl Nov 15) | B6: 377900000 | C6: V4 reconciled, sum of all cohorts
A7: BF Week peak daily GMV at risk | B7: 65200000 | C7: 14-17/11 avg, vs non-BF $7M/day
A8: Migration rate spike multiplier | B8: 2.5 | C8: V6: 31.8% BF Week vs 13% Oct baseline
A10: COHORT 1: NEW USERS
A11: User count | B11: 245131 | C11: Phase 6 Q1
A12: GMV at risk Nov | B12: 154100000 | C12: Phase 6 Q1
A13: Natural recovery rate (no program) | B13: 0.213 | C13: Phase 6 Q4
A14: AOV (abandoned cart) | B14: 440.4 | C14: Phase 6 Q1
A15: Avg sessions per user | B15: 6 | C15: Phase 6 Q1
A17: COHORT 2: OTHER OCT (Chronic Shoppers)
A18: User count | B18: 217095 | C18: Phase 6 Q1
A19: GMV at risk Nov | B19: 160100000 | C19: Phase 6 Q1
A20: Natural recovery rate | B20: 0.256 | C20: Phase 6 Q4
A21: AOV (abandoned cart) | B21: 444.58 | C21: Phase 6 Q1
A22: Avg sessions per user | B22: 14.52 | C22: Phase 6 Q1 — high engagement
A23: Sleep days Oct→Nov | B23: 17.1 | C23: Phase 6 Q2
A25: COHORT 3: STRICT DIRECT (Cannibalized VIPs)
A26: User count | B26: 36712 | C26: Phase 5 V3
A27: GMV at risk Nov | B27: 23300000 | C27: Phase 5 V3 (strict cohort)
A28: Natural recovery rate | B28: 0.385 | C28: Phase 6 Q4 — highest intent
A29: AOV migrated | B29: 338 | C29: Phase 5 V5
A30: AOV retained Direct | B30: 283 | C30: Phase 5 V5
A31: BF Week abandon rate | B31: 0.56 | C31: Phase 5 V7
A32: Non-BF Week abandon rate | B32: 0.31 | C32: Phase 5 V7 — persistence
A33: Oct baseline abandon rate | B33: 0 | C33: Phase 5 — pre-cannibalization
A35: OTHER COHORTS (not in playbook)
A36: Strict Cart cohort GMV at risk | B36: 21500000 | C36: V4
A37: Overlap cohort GMV at risk | B37: 19000000 | C37: V4
A38: Total unaddressed | B38: 40500000 | C38: 10.7% of $377.9M

Sheet Assumptions
A1: Editable Assumptions (change these cells)
A3: Assumption | B3: Conservative | C3: Base | D3: Optimistic | E3: Notes
A4: LEAK #1 NEW USERS
A5: Program recovery rate uplift (pp over natural 21.3%) | B5: 0.03 | C5: 0.07 | D5: 0.12 | E5: Industry: 5-15pp for first-order recovery
A6: Discount cost (% of recovered GMV) | B6: 0.15 | C6: 0.12 | D6: 0.08 | E6: Discount intensity decreases with maturity
A8: LEAK #2 OTHER OCT
A9: Program recovery rate uplift (pp over natural 25.6%) | B9: 0.02 | C9: 0.05 | D9: 0.1 | E9: Chronic shoppers harder to convert
A10: Discount cost (% of recovered GMV) | B10: 0.1 | C10: 0.08 | D10: 0.05 | E10: Price-drop alert less costly than new-user discount
A12: LEAK #3 STRICT DIRECT (VIPs)
A13: Program recovery rate uplift (pp over natural 38.5%) | B13: 0.05 | C13: 0.1 | D13: 0.18 | E13: Highest confidence due to intent
A14: Cannibalization prevention rate | B14: 0.2 | C14: 0.4 | D14: 0.6 | E14: % of migrated-abandoned prevented from migrating
A15: Discount cost (% of recovered GMV) | B15: 0.05 | C15: 0.03 | D15: 0 | E15: VIPs convert without heavy discount
A17: SHARED ECONOMICS
A18: Gross margin (electronics) | B18: 0.12 | C18: 0.15 | D18: 0.18 | E18: Industry 12-18% for electronics retail
A19: Setup cost one-time | B19: 300000 | C19: 240000 | D19: 180000 | E19: Dev + tooling + platform setup
A20: Annual opex | B20: 3000000 | C20: 2500000 | D20: 2000000 | E20: Platform + team + discount reserve
A21: Number of flash sale events per year | B21: 5 | C21: 7 | D21: 10 | E21: BF + Cyber + 11.11 + 12.12 + others

Sheet Calculations
A1: Per-Scenario Calculations
A2: Formulas reference Assumptions sheet. Change assumptions to see impact.
A4: Metric | B4: Conservative | C4: Base | D4: Optimistic
A5: === LEAK #1 NEW USERS ===
A6: GMV at risk | B6: =Verified_Data!B13 | C6: =Verified_Data!B13 | D6: =Verified_Data!B13
A7: Natural recovery rate | B7: =Verified_Data!B14 | C7: =Verified_Data!B14 | D7: =Verified_Data!B14
A8: Program uplift (pp) | B8: =Assumptions!B5 | C8: =Assumptions!C5 | D8: =Assumptions!D5
A9: Incremental recovery rate | B9: =B7+B6 | C9: =C7+C6 | D9: =D7+D6
A10: Recovered GMV | B10: =B6*B8 | C10: =C6*C8 | D10: =D6*D8
A11: Discount cost | B11: =B9*Assumptions!B6 | C11: =C9*Assumptions!C6 | D11: =D9*Assumptions!D6
A12: Net GMV after discount | B12: =B9-B10 | C12: =C9-C10 | D12: =D9-D10
A14: === LEAK #2 OTHER OCT ===
A15: GMV at risk | B15: =Verified_Data!B20 | C15: =Verified_Data!B20 | D15: =Verified_Data!B20
A16: Natural recovery rate | B16: =Verified_Data!B21 | C16: =Verified_Data!B21 | D16: =Verified_Data!B21
A17: Program uplift (pp) | B17: =Assumptions!B9 | C17: =Assumptions!C9 | D17: =Assumptions!D9
A18: Incremental recovery rate | B18: =B15+B14 | C18: =C15+C14 | D18: =D15+D14
A19: Recovered GMV | B19: =B14*B16 | C19: =C14*C16 | D19: =D14*D16
A20: Discount cost | B20: =B17*Assumptions!B10 | C20: =C17*Assumptions!C10 | D20: =D17*Assumptions!D10
A21: Net GMV after discount | B21: =B17-B18 | C21: =C17-C18 | D21: =D17-D18
A23: === LEAK #3 STRICT DIRECT (VIPs) ===
A24: GMV at risk | B24: =Verified_Data!B27 | C24: =Verified_Data!B27 | D24: =Verified_Data!B27
A25: Natural recovery rate | B25: =Verified_Data!B28 | C25: =Verified_Data!B28 | D25: =Verified_Data!B28
A26: Program uplift (pp) | B26: =Assumptions!B13 | C26: =Assumptions!C13 | D26: =Assumptions!D13
A27: Incremental recovery rate | B27: =B23+B22 | C27: =C23+C22 | D27: =D23+D22
A28: Recovered GMV (recovery) | B28: =B22*B24 | C28: =C22*C24 | D28: =D22*D24
A29: Cannibalization prevention rate | B29: =Assumptions!B14 | C29: =Assumptions!C14 | D29: =Assumptions!D14
A30: Prevented GMV (cannibalization) | B30: =B22*B26 | C30: =C22*C26 | D30: =D22*D26
A31: Combined Leak #3 GMV | B31: =B25+B27 | C31: =C25+C27 | D31: =D25+D27
A32: Discount cost | B32: =B28*Assumptions!B15 | C32: =C28*Assumptions!C15 | D32: =D28*Assumptions!D15
A33: Net GMV after discount | B33: =B28-B29 | C33: =C28-C29 | D33: =D28-D29
A35: === COMBINED PER BF EVENT ===
A36: Total Recovered GMV | B36: =B11+B19+B30 | C36: =C11+C19+C30 | D36: =D11+D19+D30
A37: Gross profit (margin applied) | B37: =B33*Assumptions!B19 | C37: =C33*Assumptions!C19 | D37: =D33*Assumptions!D19
A39: === ANNUAL (×events) ===
A40: Flash sale events per year | B40: =Assumptions!B22 | C40: =Assumptions!C22 | D40: =Assumptions!D22
A41: Annual recovered GMV | B41: =B33*B37 | C41: =C33*C37 | D41: =D33*D37
A42: Annual gross profit | B42: =B38*Assumptions!B19 | C42: =C38*Assumptions!C19 | D42: =D38*Assumptions!D19
A43: Annual opex | B43: =Assumptions!B21 | C43: =Assumptions!C21 | D43: =Assumptions!D21
A44: Setup cost (one-time) | B44: =Assumptions!B20 | C44: =Assumptions!C20 | D44: =Assumptions!D20
A45: Net profit year 1 | B45: =B39-B40-B41 | C45: =C39-C40-C41 | D45: =D39-D40-D41
...

Sheet Scenarios
A1: Scenario Comparison
A3: Metric | B3: Conservative | C3: Base | D3: Optimistic
A4: PER BF EVENT
A5: Leak #1 Net Recovery | B5: =Calculations!B11 | C5: =Calculations!C11 | D5: =Calculations!D11
A6: Leak #2 Net Recovery | B6: =Calculations!B19 | C6: =Calculations!C19 | D6: =Calculations!D19
A7: Leak #3 Net Recovery (recovery + prevention) | B7: =Calculations!B30 | C7: =Calculations!C30 | D7: =Calculations!D30
A8: TOTAL per BF event | B8: =SUM(B5:B7) | C8: =SUM(C5:C7) | D8: =SUM(D5:D7)
A10: ANNUAL
A11: Annual Recovered GMV | B11: =Calculations!B38 | C11: =Calculations!C38 | D11: =Calculations!D38
A12: Annual Gross Profit | B12: =Calculations!B39 | C12: =Calculations!C39 | D12: =Calculations!D39
A13: Annual Opex | B13: =Calculations!B40 | C13: =Calculations!C40 | D13: =Calculations!D40
A14: Setup (one-time) | B14: =Calculations!B41 | C14: =Calculations!C41 | D14: =Calculations!D41
A15: NET PROFIT YEAR 1 | B15: =Calculations!B42 | C15: =Calculations!C42 | D15: =Calculations!D42
A16: ROI YEAR 1 | B16: =Calculations!B43 | C16: =Calculations!C43 | D16: =Calculations!D43

Sheet Sensitivity
A1: Sensitivity: Recovery Uplift × Discount Cost (Base Scenario Combined)
A2: Values = Combined net recovered GMV per BF event (USD)
A4: Uplift pp ↓ | Discount → | B4: 0 | C4: 0.05 | D4: 0.1 | E4: 0.15 | F4: 0.2 | G4: 0.25
A5: 0.02 | B5: 6750000 | C5: 6412500 | D5: 6075000 | E5: 5737500 | F5: 5400000 | G5: 5062500
A6: 0.05 | B6: 16875000 | C6: 16031250 | D6: 15187500 | E6: 14343750 | F6: 13500000 | G6: 12656250
A7: 0.08 | B7: 27000000 | C7: 25650000 | D7: 24300000 | E7: 22950000 | F7: 21600000 | G7: 20250000
A8: 0.12 | B8: 40500000 | C8: 38475000 | D8: 36450000 | E8: 34425000 | F8: 32400000 | G8: 30375000
A9: 0.15 | B9: 50625000 | C9: 48093750 | D9: 45562500 | E9: 43031250 | F9: 40500000 | G9: 37968750
A10: 0.2 | B10: 67500000 | C10: 64125000 | D10: 60750000 | E10: 57375000 | F10: 54000000 | G10: 50625000
A13: Legend
A14: Rows: Program recovery rate uplift over natural baseline (pp)
A15: Cols: Discount cost as % of recovered GMV
A16: Cells: Net recovered GMV per BF event, in $M
A17: Baseline: Combined GMV at risk $337.5M across 3 cohorts

Sheet Annual_Projection
A1: 12-Month Flash Sale Compounding Projection (Base Case)
A3: Event | B3: Scale vs BF | C3: Leak #1 ($) | D3: Leak #2 ($) | E3: Leak #3 ($) | F3: Total Recovery ($) | G3: Cumulative ($)
A4: Black Friday (Nov) | B4: 1 | C4: 15000000 | D4: 13000000 | E4: 18000000 | F4: 46000000 | G4: 46000000
A5: Cyber Monday (Dec) | B5: 0.6 | C5: 9000000 | D5: 7800000 | E5: 10800000 | F5: 27600000 | G5: 73600000
A6: Christmas Sale (Dec) | B6: 0.5 | C6: 7500000 | D6: 6500000 | E6: 9000000 | F6: 23000000 | G6: 96600000
A7: 11.11 Russia | B7: 0.7 | C7: 10500000 | D7: 9100000 | E7: 12600000 | F7: 32200000 | G7: 128800000
A8: 12.12 Sale | B8: 0.5 | C8: 7500000 | D8: 6500000 | E8: 9000000 | F8: 23000000 | G8: 151800000
A9: International Women's Day (Mar) | B9: 0.4 | C9: 6000000 | D9: 5200000 | E9: 7200000 | F9: 18400000 | G9: 170200000
A10: Mother's Day (May) | B10: 0.3 | C10: 4500000 | D10: 3900000 | E10: 5400000 | F10: 13800000 | G10: 184000000
A11: ANNUAL TOTAL | C11: =SUM(C4:C10) | D11: =SUM(D4:D10) | E11: =SUM(E4:E10) | F11: =SUM(F4:F10)
